<?xml version="1.0" encoding="utf-8"?>
<!-- =================================================================================== -->
<!-- |    This document was autogenerated by xacro from rob1_rob2_multiarm.urdf.xacro  | -->
<!-- |    EDITING THIS FILE BY HAND IS NOT RECOMMENDED                                 | -->
<!-- =================================================================================== -->
<robot name="dual_robot">
  <gazebo>
    <plugin filename="libgazebo_ros_control.so" name="ros_control">
      <!--robotNamespace>/</robotNamespace-->
      <!--robotSimType>gazebo_ros_control/DefaultRobotHWSim</robotSimType-->
    </plugin>
    <!--
    <plugin name="gazebo_ros_power_monitor_controller" filename="libgazebo_ros_power_monitor.so">
      <alwaysOn>true</alwaysOn>
      <updateRate>1.0</updateRate>
      <timeout>5</timeout>
      <powerStateTopic>power_state</powerStateTopic>
      <powerStateRate>10.0</powerStateRate>
      <fullChargeCapacity>87.78</fullChargeCapacity>     
      <dischargeRate>-474</dischargeRate>
      <chargeRate>525</chargeRate>
      <dischargeVoltage>15.52</dischargeVoltage>
      <chargeVoltage>16.41</chargeVoltage>
    </plugin>
-->
  </gazebo>
  <!-- realsense d435 -->
  <!--   <xacro:include filename="$(find realsense2_description)/urdf/_d435.urdf.xacro" /> -->
  <!-- measured from model -->
  <!-- link lengths used in model -->
  <!-- manually measured -->
  <link name="rob1_base_link">
    <visual>
      <origin rpy="0 0 3.14159265359" xyz="0 0 0"/>
      <geometry>
        <mesh filename="package://ur_e_description/meshes/ur5e/visual/base.dae"/>
      </geometry>
      <material name="LightGrey">
        <color rgba="0.7 0.7 0.7 1.0"/>
      </material>
    </visual>
    <collision>
      <origin rpy="0 0 3.14159265359" xyz="0 0 0"/>
      <geometry>
        <mesh filename="package://ur_e_description/meshes/ur5e/collision/base.stl"/>
      </geometry>
    </collision>
    <inertial>
      <mass value="4.0"/>
      <origin rpy="0 0 0" xyz="0.0 0.0 0.0"/>
      <inertia ixx="0.00443333156" ixy="0.0" ixz="0.0" iyy="0.00443333156" iyz="0.0" izz="0.0072"/>
    </inertial>
  </link>
  <joint name="rob1_shoulder_pan_joint" type="revolute">
    <parent link="rob1_base_link"/>
    <child link="rob1_shoulder_link"/>
    <origin rpy="0 0 3.14159265359" xyz="0 0 0.1625"/>
    <axis xyz="0 0 1"/>
    <limit effort="150.0" lower="-6.28318530718" upper="6.28318530718" velocity="3.14"/>
    <dynamics damping="0.0" friction="0.0"/>
  </joint>
  <link name="rob1_shoulder_link">
    <visual>
      <origin rpy="0 0 3.14159265359" xyz="0 0 0"/>
      <geometry>
        <mesh filename="package://ur_e_description/meshes/ur5e/visual/shoulder.dae"/>
      </geometry>
      <material name="LightGrey">
        <color rgba="0.7 0.7 0.7 1.0"/>
      </material>
    </visual>
    <collision>
      <origin rpy="0 0 3.14159265359" xyz="0 0 0"/>
      <geometry>
        <mesh filename="package://ur_e_description/meshes/ur5e/collision/shoulder.stl"/>
      </geometry>
    </collision>
    <inertial>
      <mass value="3.7"/>
      <origin rpy="0 0 0" xyz="0.0 0.0 0.0"/>
      <inertia ixx="0.010267495893" ixy="0.0" ixz="0.0" iyy="0.010267495893" iyz="0.0" izz="0.00666"/>
    </inertial>
  </link>
  <joint name="rob1_shoulder_lift_joint" type="revolute">
    <parent link="rob1_shoulder_link"/>
    <child link="rob1_upper_arm_link"/>
    <origin rpy="1.570796327 0 0" xyz="0 0 0"/>
    <axis xyz="0 0 1"/>
    <limit effort="150.0" lower="-6.28318530718" upper="6.28318530718" velocity="3.14"/>
    <dynamics damping="0.0" friction="0.0"/>
  </joint>
  <link name="rob1_upper_arm_link">
    <visual>
      <origin rpy="1.57079632679 0 -1.57079632679" xyz="0 0 0.138"/>
      <geometry>
        <mesh filename="package://ur_e_description/meshes/ur5e/visual/upperarm.dae"/>
      </geometry>
      <material name="LightGrey">
        <color rgba="0.7 0.7 0.7 1.0"/>
      </material>
    </visual>
    <collision>
      <origin rpy="1.57079632679 0 -1.57079632679" xyz="0 0 0.138"/>
      <geometry>
        <mesh filename="package://ur_e_description/meshes/ur5e/collision/upperarm.stl"/>
      </geometry>
    </collision>
    <inertial>
      <mass value="8.393"/>
      <origin rpy="0 1.57079632679 0" xyz="-0.2125 0.0 0.138"/>
      <inertia ixx="0.138134736413" ixy="0.0" ixz="0.0" iyy="0.138134736413" iyz="0.0" izz="0.0236053125"/>
    </inertial>
  </link>
  <joint name="rob1_elbow_joint" type="revolute">
    <parent link="rob1_upper_arm_link"/>
    <child link="rob1_forearm_link"/>
    <origin rpy="0 0 0" xyz="-0.425 0 0"/>
    <axis xyz="0 0 1"/>
    <limit effort="150.0" lower="-3.14159265359" upper="3.14159265359" velocity="3.14"/>
    <dynamics damping="0.0" friction="0.0"/>
  </joint>
  <link name="rob1_forearm_link">
    <visual>
      <origin rpy="1.57079632679 0 -1.57079632679" xyz="0 0 0.007"/>
      <geometry>
        <mesh filename="package://ur_e_description/meshes/ur5e/visual/forearm.dae"/>
      </geometry>
      <material name="LightGrey">
        <color rgba="0.7 0.7 0.7 1.0"/>
      </material>
    </visual>
    <collision>
      <origin rpy="1.57079632679 0 -1.57079632679" xyz="0 0 0.007"/>
      <geometry>
        <mesh filename="package://ur_e_description/meshes/ur5e/collision/forearm.stl"/>
      </geometry>
    </collision>
    <inertial>
      <mass value="2.275"/>
      <origin rpy="0 1.57079632679 0" xyz="-0.2125 0.0 0.007"/>
      <inertia ixx="0.0323610733889" ixy="0.0" ixz="0.0" iyy="0.0323610733889" iyz="0.0" izz="0.0063984375"/>
    </inertial>
  </link>
  <joint name="rob1_wrist_1_joint" type="revolute">
    <parent link="rob1_forearm_link"/>
    <child link="rob1_wrist_1_link"/>
    <origin rpy="0 0 0" xyz="-0.3922 0 0.1333"/>
    <axis xyz="0 0 1"/>
    <limit effort="28.0" lower="-6.28318530718" upper="6.28318530718" velocity="6.28"/>
    <dynamics damping="0.0" friction="0.0"/>
  </joint>
  <link name="rob1_wrist_1_link">
    <visual>
      <origin rpy="1.57079632679 0 0" xyz="0 0 -0.127"/>
      <geometry>
        <mesh filename="package://ur_e_description/meshes/ur5e/visual/wrist1.dae"/>
      </geometry>
      <material name="LightGrey">
        <color rgba="0.7 0.7 0.7 1.0"/>
      </material>
    </visual>
    <collision>
      <origin rpy="1.57079632679 0 0" xyz="0 0 -0.127"/>
      <geometry>
        <mesh filename="package://ur_e_description/meshes/ur5e/collision/wrist1.stl"/>
      </geometry>
    </collision>
    <inertial>
      <mass value="1.219"/>
      <origin rpy="0 0 0" xyz="0.0 0.0 0.0"/>
      <inertia ixx="0.00272396513625" ixy="0.0" ixz="0.0" iyy="0.00272396513625" iyz="0.0" izz="0.0034284375"/>
    </inertial>
  </link>
  <joint name="rob1_wrist_2_joint" type="revolute">
    <parent link="rob1_wrist_1_link"/>
    <child link="rob1_wrist_2_link"/>
    <origin rpy="1.570796327 0 0" xyz="0 -0.0997 -2.0448811823e-11"/>
    <axis xyz="0 0 1"/>
    <limit effort="28.0" lower="-6.28318530718" upper="6.28318530718" velocity="6.28"/>
    <dynamics damping="0.0" friction="0.0"/>
  </joint>
  <link name="rob1_wrist_2_link">
    <visual>
      <origin rpy="0 0 0" xyz="0 0 -0.0997"/>
      <geometry>
        <mesh filename="package://ur_e_description/meshes/ur5e/visual/wrist2.dae"/>
      </geometry>
      <material name="LightGrey">
        <color rgba="0.7 0.7 0.7 1.0"/>
      </material>
    </visual>
    <collision>
      <origin rpy="0 0 0" xyz="0 0 -0.0997"/>
      <geometry>
        <mesh filename="package://ur_e_description/meshes/ur5e/collision/wrist2.stl"/>
      </geometry>
    </collision>
    <inertial>
      <mass value="1.219"/>
      <origin rpy="0 0 0" xyz="0.0 0.0 0.0"/>
      <inertia ixx="0.00272194058122" ixy="0.0" ixz="0.0" iyy="0.00272194058122" iyz="0.0" izz="0.0034284375"/>
    </inertial>
  </link>
  <joint name="rob1_wrist_3_joint" type="revolute">
    <parent link="rob1_wrist_2_link"/>
    <child link="rob1_wrist_3_link"/>
    <origin rpy="1.57079632659 3.14159265359 3.14159265359" xyz="0 0.0996 -2.04283014801e-11"/>
    <axis xyz="0 0 1"/>
    <limit effort="28.0" lower="-6.28318530718" upper="6.28318530718" velocity="6.28"/>
    <dynamics damping="0.0" friction="0.0"/>
  </joint>
  <link name="rob1_wrist_3_link">
    <visual>
      <origin rpy="1.57079632679 0 0" xyz="0 0 -0.0989"/>
      <geometry>
        <mesh filename="package://ur_e_description/meshes/ur5e/visual/wrist3.dae"/>
      </geometry>
      <material name="LightGrey">
        <color rgba="0.7 0.7 0.7 1.0"/>
      </material>
    </visual>
    <collision>
      <origin rpy="1.57079632679 0 0" xyz="0 0 -0.0989"/>
      <geometry>
        <mesh filename="package://ur_e_description/meshes/ur5e/collision/wrist3.stl"/>
      </geometry>
    </collision>
    <inertial>
      <mass value="0.1879"/>
      <origin rpy="0 0 0" xyz="0.0 0.0 -0.025"/>
      <inertia ixx="0.000134270154625" ixy="0.0" ixz="0.0" iyy="0.000134270154625" iyz="0.0" izz="0.00019024875"/>
    </inertial>
  </link>
  <joint name="rob1_ee_fixed_joint" type="fixed">
    <parent link="rob1_wrist_3_link"/>
    <child link="rob1_ee_link"/>
    <origin rpy="0.0 -1.57079632679 1.57079632679" xyz="0.0 0.0 0.0"/>
  </joint>
  <link name="rob1_ee_link">
    <collision>
      <geometry>
        <box size="0.01 0.01 0.01"/>
      </geometry>
      <origin rpy="0 0 0" xyz="-0.01 0 0"/>
    </collision>
  </link>
  <transmission name="rob1_shoulder_pan_trans">
    <type>transmission_interface/SimpleTransmission</type>
    <joint name="rob1_shoulder_pan_joint">
      <hardwareInterface>hardware_interface/PositionJointInterface</hardwareInterface>
    </joint>
    <actuator name="rob1_shoulder_pan_motor">
      <mechanicalReduction>1</mechanicalReduction>
    </actuator>
  </transmission>
  <transmission name="rob1_shoulder_lift_trans">
    <type>transmission_interface/SimpleTransmission</type>
    <joint name="rob1_shoulder_lift_joint">
      <hardwareInterface>hardware_interface/PositionJointInterface</hardwareInterface>
    </joint>
    <actuator name="rob1_shoulder_lift_motor">
      <mechanicalReduction>1</mechanicalReduction>
    </actuator>
  </transmission>
  <transmission name="rob1_elbow_trans">
    <type>transmission_interface/SimpleTransmission</type>
    <joint name="rob1_elbow_joint">
      <hardwareInterface>hardware_interface/PositionJointInterface</hardwareInterface>
    </joint>
    <actuator name="rob1_elbow_motor">
      <mechanicalReduction>1</mechanicalReduction>
    </actuator>
  </transmission>
  <transmission name="rob1_wrist_1_trans">
    <type>transmission_interface/SimpleTransmission</type>
    <joint name="rob1_wrist_1_joint">
      <hardwareInterface>hardware_interface/PositionJointInterface</hardwareInterface>
    </joint>
    <actuator name="rob1_wrist_1_motor">
      <mechanicalReduction>1</mechanicalReduction>
    </actuator>
  </transmission>
  <transmission name="rob1_wrist_2_trans">
    <type>transmission_interface/SimpleTransmission</type>
    <joint name="rob1_wrist_2_joint">
      <hardwareInterface>hardware_interface/PositionJointInterface</hardwareInterface>
    </joint>
    <actuator name="rob1_wrist_2_motor">
      <mechanicalReduction>1</mechanicalReduction>
    </actuator>
  </transmission>
  <transmission name="rob1_wrist_3_trans">
    <type>transmission_interface/SimpleTransmission</type>
    <joint name="rob1_wrist_3_joint">
      <hardwareInterface>hardware_interface/PositionJointInterface</hardwareInterface>
    </joint>
    <actuator name="rob1_wrist_3_motor">
      <mechanicalReduction>1</mechanicalReduction>
    </actuator>
  </transmission>
  <gazebo reference="rob1_shoulder_link">
    <selfCollide>true</selfCollide>
  </gazebo>
  <gazebo reference="rob1_upper_arm_link">
    <selfCollide>true</selfCollide>
  </gazebo>
  <gazebo reference="rob1_forearm_link">
    <selfCollide>true</selfCollide>
  </gazebo>
  <gazebo reference="rob1_wrist_1_link">
    <selfCollide>true</selfCollide>
  </gazebo>
  <gazebo reference="rob1_wrist_3_link">
    <selfCollide>true</selfCollide>
  </gazebo>
  <gazebo reference="rob1_wrist_2_link">
    <selfCollide>true</selfCollide>
  </gazebo>
  <gazebo reference="rob1_ee_link">
    <selfCollide>true</selfCollide>
  </gazebo>
  <!-- ROS base_link to UR 'Base' Coordinates transform -->
  <link name="rob1_base"/>
  <joint name="rob1_base_link-base_fixed_joint" type="fixed">
    <!-- NOTE: this rotation is only needed as long as base_link itself is
                 not corrected wrt the real robot (ie: rotated over 180
                 degrees)
      -->
    <origin rpy="0 0 -3.14159265359" xyz="0 0 0"/>
    <parent link="rob1_base_link"/>
    <child link="rob1_base"/>
  </joint>
  <!-- Frame coincident with all-zeros TCP on UR controller -->
  <link name="rob1_tool0"/>
  <joint name="rob1_wrist_3_link-tool0_fixed_joint" type="fixed">
    <origin rpy="0 0 0" xyz="0 0 0"/>
    <parent link="rob1_wrist_3_link"/>
    <child link="rob1_tool0"/>
  </joint>
  <link name="rob1_robotiq_arg2f_base_link">
    <inertial>
      <origin rpy="0 0 0" xyz="8.625E-08 -4.6583E-06 0.03145"/>
      <mass value="0.22652"/>
      <inertia ixx="0.00020005" ixy="-4.2442E-10" ixz="-2.9069E-10" iyy="0.00017832" iyz="-3.4402E-08" izz="0.00013478"/>
    </inertial>
    <visual>
      <origin rpy="0 0 0" xyz="0 0 0"/>
      <geometry>
        <mesh filename="package://robotiq_2f_85_gripper_visualization/meshes/visual/robotiq_arg2f_85_base_link.dae" scale="0.001 0.001 0.001"/>
      </geometry>
      <material name="">
        <color rgba="0.1 0.1 0.1 1"/>
      </material>
    </visual>
    <collision>
      <origin rpy="0 0 0" xyz="0 0 0"/>
      <geometry>
        <mesh filename="package://robotiq_2f_85_gripper_visualization/meshes/collision/robotiq_arg2f_base_link.stl"/>
      </geometry>
    </collision>
  </link>
  <link name="rob1_left_outer_knuckle">
    <!--<inertial>
        <origin xyz="-0.000200000000003065 0.0199435877845359 0.0292245259211331" rpy="0 0 0" />
        <mass value="0.00853198276973456" />
        <inertia ixx="2.89328108496468E-06" ixy="-1.57935047237397E-19" ixz="-1.93980378593255E-19" iyy="1.86719750325683E-06" iyz="-1.21858577871576E-06" izz="1.21905238907251E-06" />
        </inertial> -->
    <visual>
      <origin rpy="0 0 0" xyz="0 0 0"/>
      <geometry>
        <mesh filename="package://robotiq_2f_85_gripper_visualization/meshes/visual/robotiq_arg2f_85_outer_knuckle.dae" scale="0.001 0.001 0.001"/>
      </geometry>
      <material name="">
        <color rgba="0.792156862745098 0.819607843137255 0.933333333333333 1"/>
      </material>
    </visual>
    <collision>
      <origin rpy="0 0 0" xyz="0 0 0"/>
      <geometry>
        <mesh filename="package://robotiq_2f_85_gripper_visualization/meshes/collision/robotiq_arg2f_85_outer_knuckle.dae" scale="0.001 0.001 0.001"/>
      </geometry>
    </collision>
  </link>
  <link name="rob1_left_outer_finger">
    <!--<inertial>
        <origin xyz="0.00030115855001899 0.0373907951953854 -0.0208027427000385" rpy="0 0 0" />
        <mass value="0.022614240507152" />
        <inertia ixx="1.52518312458174E-05" ixy="9.76583423954399E-10" ixz="-5.43838577022588E-10" iyy="6.17694243867776E-06" iyz="6.78636130740228E-06" izz="1.16494917907219E-05" />
        </inertial> -->
    <visual>
      <origin rpy="0 0 0" xyz="0 0 0"/>
      <geometry>
        <mesh filename="package://robotiq_2f_85_gripper_visualization/meshes/visual/robotiq_arg2f_85_outer_finger.dae" scale="0.001 0.001 0.001"/>
      </geometry>
      <material name="">
        <color rgba="0.1 0.1 0.1 1"/>
      </material>
    </visual>
    <collision>
      <origin rpy="0 0 0" xyz="0 0 0"/>
      <geometry>
        <mesh filename="package://robotiq_2f_85_gripper_visualization/meshes/collision/robotiq_arg2f_85_outer_finger.dae" scale="0.001 0.001 0.001"/>
      </geometry>
    </collision>
  </link>
  <link name="rob1_left_inner_finger">
    <!--<inertial>
        <origin xyz="0.000299999999999317 0.0160078233491243 -0.0136945669206257" rpy="0 0 0" />
        <mass value="0.0104003125914103" />
        <inertia ixx="2.71909453810972E-06" ixy="1.35402465472579E-21" ixz="-7.1817349065269E-22" iyy="7.69100314106116E-07" iyz="6.74715432769696E-07" izz="2.30315190420171E-06" />
        </inertial> -->
    <visual>
      <origin rpy="0 0 0" xyz="0 0 0"/>
      <geometry>
        <mesh filename="package://robotiq_2f_85_gripper_visualization/meshes/visual/robotiq_arg2f_85_inner_finger.dae" scale="0.001 0.001 0.001"/>
      </geometry>
      <material name="">
        <color rgba="0.1 0.1 0.1 1"/>
      </material>
    </visual>
    <collision>
      <origin rpy="0 0 0" xyz="0 0 0"/>
      <geometry>
        <mesh filename="package://robotiq_2f_85_gripper_visualization/meshes/collision/robotiq_arg2f_85_inner_finger.dae" scale="0.001 0.001 0.001"/>
      </geometry>
    </collision>
  </link>
  <link name="rob1_left_inner_finger_pad">
    <visual>
      <origin rpy="0 0 0" xyz="0 0 0.005"/>
      <geometry>
        <box size="0.022 0.00635 0.0375"/>
      </geometry>
      <material name="">
        <color rgba="0.9 0.9 0.9 1"/>
      </material>
    </visual>
    <collision>
      <origin rpy="0 0 0" xyz="0 0 0.005"/>
      <geometry>
        <box size="0.022 0.00635 0.0375"/>
      </geometry>
      <material name="">
        <color rgba="0.9 0.0 0.0 1"/>
      </material>
    </collision>
  </link>
  <link name="rob1_left_inner_knuckle">
    <!--<inertial>
        <origin xyz="0.000123011831763771 0.0507850843201817 0.00103968640075166" rpy="0 0 0" />
       <mass value="0.0271177346495152" />
        <inertia ixx="2.61910379223783E-05" ixy="-2.43616858946494E-07" ixz="-6.37789906117123E-09" iyy="2.8270243746167E-06" iyz="-5.37200748039765E-07" izz="2.83695868220296E-05" />
        </inertial> -->
    <visual>
      <origin rpy="0 0 0" xyz="0 0 0"/>
      <geometry>
        <mesh filename="package://robotiq_2f_85_gripper_visualization/meshes/visual/robotiq_arg2f_85_inner_knuckle.dae" scale="0.001 0.001 0.001"/>
      </geometry>
      <material name="">
        <color rgba="0.1 0.1 0.1 1"/>
      </material>
    </visual>
    <collision>
      <origin rpy="0 0 0" xyz="0 0 0"/>
      <geometry>
        <mesh filename="package://robotiq_2f_85_gripper_visualization/meshes/collision/robotiq_arg2f_85_inner_knuckle.dae" scale="0.001 0.001 0.001"/>
      </geometry>
    </collision>
  </link>
  <link name="rob1_right_outer_knuckle">
    <!--<inertial>
        <origin xyz="-0.000200000000003065 0.0199435877845359 0.0292245259211331" rpy="0 0 0" />
        <mass value="0.00853198276973456" />
        <inertia ixx="2.89328108496468E-06" ixy="-1.57935047237397E-19" ixz="-1.93980378593255E-19" iyy="1.86719750325683E-06" iyz="-1.21858577871576E-06" izz="1.21905238907251E-06" />
        </inertial> -->
    <visual>
      <origin rpy="0 0 0" xyz="0 0 0"/>
      <geometry>
        <mesh filename="package://robotiq_2f_85_gripper_visualization/meshes/visual/robotiq_arg2f_85_outer_knuckle.dae" scale="0.001 0.001 0.001"/>
      </geometry>
      <material name="">
        <color rgba="0.792156862745098 0.819607843137255 0.933333333333333 1"/>
      </material>
    </visual>
    <collision>
      <origin rpy="0 0 0" xyz="0 0 0"/>
      <geometry>
        <mesh filename="package://robotiq_2f_85_gripper_visualization/meshes/collision/robotiq_arg2f_85_outer_knuckle.dae" scale="0.001 0.001 0.001"/>
      </geometry>
    </collision>
  </link>
  <link name="rob1_right_outer_finger">
    <!--<inertial>
        <origin xyz="0.00030115855001899 0.0373907951953854 -0.0208027427000385" rpy="0 0 0" />
        <mass value="0.022614240507152" />
        <inertia ixx="1.52518312458174E-05" ixy="9.76583423954399E-10" ixz="-5.43838577022588E-10" iyy="6.17694243867776E-06" iyz="6.78636130740228E-06" izz="1.16494917907219E-05" />
        </inertial> -->
    <visual>
      <origin rpy="0 0 0" xyz="0 0 0"/>
      <geometry>
        <mesh filename="package://robotiq_2f_85_gripper_visualization/meshes/visual/robotiq_arg2f_85_outer_finger.dae" scale="0.001 0.001 0.001"/>
      </geometry>
      <material name="">
        <color rgba="0.1 0.1 0.1 1"/>
      </material>
    </visual>
    <collision>
      <origin rpy="0 0 0" xyz="0 0 0"/>
      <geometry>
        <mesh filename="package://robotiq_2f_85_gripper_visualization/meshes/collision/robotiq_arg2f_85_outer_finger.dae" scale="0.001 0.001 0.001"/>
      </geometry>
    </collision>
  </link>
  <link name="rob1_right_inner_finger">
    <!--<inertial>
        <origin xyz="0.000299999999999317 0.0160078233491243 -0.0136945669206257" rpy="0 0 0" />
        <mass value="0.0104003125914103" />
        <inertia ixx="2.71909453810972E-06" ixy="1.35402465472579E-21" ixz="-7.1817349065269E-22" iyy="7.69100314106116E-07" iyz="6.74715432769696E-07" izz="2.30315190420171E-06" />
        </inertial> -->
    <visual>
      <origin rpy="0 0 0" xyz="0 0 0"/>
      <geometry>
        <mesh filename="package://robotiq_2f_85_gripper_visualization/meshes/visual/robotiq_arg2f_85_inner_finger.dae" scale="0.001 0.001 0.001"/>
      </geometry>
      <material name="">
        <color rgba="0.1 0.1 0.1 1"/>
      </material>
    </visual>
    <collision>
      <origin rpy="0 0 0" xyz="0 0 0"/>
      <geometry>
        <mesh filename="package://robotiq_2f_85_gripper_visualization/meshes/collision/robotiq_arg2f_85_inner_finger.dae" scale="0.001 0.001 0.001"/>
      </geometry>
    </collision>
  </link>
  <link name="rob1_right_inner_finger_pad">
    <visual>
      <origin rpy="0 0 0" xyz="0 0 0.005"/>
      <geometry>
        <box size="0.022 0.00635 0.0375"/>
      </geometry>
      <material name="">
        <color rgba="0.9 0.9 0.9 1"/>
      </material>
    </visual>
    <collision>
      <origin rpy="0 0 0" xyz="0 0 0.005"/>
      <geometry>
        <box size="0.022 0.00635 0.0375"/>
      </geometry>
      <material name="">
        <color rgba="0.9 0.0 0.0 1"/>
      </material>
    </collision>
  </link>
  <link name="rob1_right_inner_knuckle">
    <!--<inertial>
        <origin xyz="0.000123011831763771 0.0507850843201817 0.00103968640075166" rpy="0 0 0" />
       <mass value="0.0271177346495152" />
        <inertia ixx="2.61910379223783E-05" ixy="-2.43616858946494E-07" ixz="-6.37789906117123E-09" iyy="2.8270243746167E-06" iyz="-5.37200748039765E-07" izz="2.83695868220296E-05" />
        </inertial> -->
    <visual>
      <origin rpy="0 0 0" xyz="0 0 0"/>
      <geometry>
        <mesh filename="package://robotiq_2f_85_gripper_visualization/meshes/visual/robotiq_arg2f_85_inner_knuckle.dae" scale="0.001 0.001 0.001"/>
      </geometry>
      <material name="">
        <color rgba="0.1 0.1 0.1 1"/>
      </material>
    </visual>
    <collision>
      <origin rpy="0 0 0" xyz="0 0 0"/>
      <geometry>
        <mesh filename="package://robotiq_2f_85_gripper_visualization/meshes/collision/robotiq_arg2f_85_inner_knuckle.dae" scale="0.001 0.001 0.001"/>
      </geometry>
    </collision>
  </link>
  <joint name="rob1_finger_joint" type="revolute">
    <origin rpy="0 0 3.14159265359" xyz="0 -0.0306011 0.054904"/>
    <parent link="rob1_robotiq_arg2f_base_link"/>
    <child link="rob1_left_outer_knuckle"/>
    <axis xyz="1 0 0"/>
    <limit effort="1000" lower="0" upper="0.8" velocity="2.0"/>
  </joint>
  <joint name="rob1_left_outer_finger_joint" type="fixed">
    <origin rpy="0 0 0" xyz="0 0.0315 -0.0041"/>
    <parent link="rob1_left_outer_knuckle"/>
    <child link="rob1_left_outer_finger"/>
    <axis xyz="1 0 0"/>
  </joint>
  <joint name="rob1_left_inner_knuckle_joint" type="revolute">
    <!-- <origin xyz="0 ${reflect * -0.0127} 0.06142" rpy="${pi / 2 + .725} 0 ${(reflect - 1) * pi / 2}" /> -->
    <origin rpy="0 0 3.14159265359" xyz="0 -0.0127 0.06142"/>
    <parent link="rob1_robotiq_arg2f_base_link"/>
    <child link="rob1_left_inner_knuckle"/>
    <axis xyz="1 0 0"/>
    <limit effort="1000" lower="0" upper="0.8757" velocity="2.0"/>
    <mimic joint="rob1_finger_joint" multiplier="1" offset="0"/>
  </joint>
  <joint name="rob1_left_inner_finger_joint" type="revolute">
    <origin rpy="0 0 0" xyz="0 0.0061 0.0471"/>
    <parent link="rob1_left_outer_finger"/>
    <child link="rob1_left_inner_finger"/>
    <axis xyz="1 0 0"/>
    <limit effort="1000" lower="0" upper="0.8757" velocity="2.0"/>
    <mimic joint="rob1_finger_joint" multiplier="-1" offset="0"/>
  </joint>
  <joint name="rob1_left_inner_finger_pad_joint" type="fixed">
    <origin rpy="0 0 0" xyz="0 -0.0220203446692936 0.03242"/>
    <parent link="rob1_left_inner_finger"/>
    <child link="rob1_left_inner_finger_pad"/>
    <axis xyz="0 0 1"/>
  </joint>
  <joint name="rob1_right_outer_knuckle_joint" type="revolute">
    <origin rpy="0 0 0" xyz="0 0.0306011 0.054904"/>
    <parent link="rob1_robotiq_arg2f_base_link"/>
    <child link="rob1_right_outer_knuckle"/>
    <axis xyz="1 0 0"/>
    <limit effort="1000" lower="0" upper="0.81" velocity="2.0"/>
    <mimic joint="rob1_finger_joint" multiplier="1" offset="0"/>
  </joint>
  <joint name="rob1_right_outer_finger_joint" type="fixed">
    <origin rpy="0 0 0" xyz="0 0.0315 -0.0041"/>
    <parent link="rob1_right_outer_knuckle"/>
    <child link="rob1_right_outer_finger"/>
    <axis xyz="1 0 0"/>
  </joint>
  <joint name="rob1_right_inner_knuckle_joint" type="revolute">
    <!-- <origin xyz="0 ${reflect * -0.0127} 0.06142" rpy="${pi / 2 + .725} 0 ${(reflect - 1) * pi / 2}" /> -->
    <origin rpy="0 0 0.0" xyz="0 0.0127 0.06142"/>
    <parent link="rob1_robotiq_arg2f_base_link"/>
    <child link="rob1_right_inner_knuckle"/>
    <axis xyz="1 0 0"/>
    <limit effort="1000" lower="0" upper="0.8757" velocity="2.0"/>
    <mimic joint="rob1_finger_joint" multiplier="1" offset="0"/>
  </joint>
  <joint name="rob1_right_inner_finger_joint" type="revolute">
    <origin rpy="0 0 0" xyz="0 0.0061 0.0471"/>
    <parent link="rob1_right_outer_finger"/>
    <child link="rob1_right_inner_finger"/>
    <axis xyz="1 0 0"/>
    <limit effort="1000" lower="0" upper="0.8757" velocity="2.0"/>
    <mimic joint="rob1_finger_joint" multiplier="-1" offset="0"/>
  </joint>
  <joint name="rob1_right_inner_finger_pad_joint" type="fixed">
    <origin rpy="0 0 0" xyz="0 -0.0220203446692936 0.03242"/>
    <parent link="rob1_right_inner_finger"/>
    <child link="rob1_right_inner_finger_pad"/>
    <axis xyz="0 0 1"/>
  </joint>
  <transmission name="rob1_finger_joint_trans">
    <type>transmission_interface/SimpleTransmission</type>
    <joint name="rob1_finger_joint">
      <hardwareInterface>PositionJointInterface</hardwareInterface>
    </joint>
    <actuator name="rob1_finger_joint_motor">
      <mechanicalReduction>1</mechanicalReduction>
    </actuator>
  </transmission>
  <link name="rob1_real_base_link"/>
  <joint name="rob1_real_base_joint" type="fixed">
    <parent link="rob1_real_base_link"/>
    <child link="rob1_base_link"/>
    <origin rpy="0.0 0.0 3.14159" xyz="0 0.0 0.0"/>
  </joint>
  <link name="rob1_world"/>
  <joint name="rob1_world_base_joint" type="fixed">
    <parent link="rob1_world"/>
    <child link="rob1_real_base_link"/>
    <origin rpy="0.0 0.0 0" xyz="0 0.0 0.0"/>
  </joint>
  <joint name="rob1_ur_real_ee_fixed_joint" type="fixed">
    <parent link="rob1_ee_link"/>
    <child link="rob1_real_ee_link"/>
    <origin rpy="-1.570795 0.0 -1.570795" xyz="0.0 0.0 0.0"/>
  </joint>
  <link name="rob1_real_ee_link"/>
  <!-- for grasp point -->
  <link name="rob1_tcp_gripper_open"/>
  <link name="rob1_tcp_gripper_closed"/>
  <joint name="rob1_ur_tcp_fixed_joint" type="fixed">
    <parent link="rob1_real_ee_link"/>
    <child link="rob1_tcp_gripper_open"/>
    <origin rpy="0 0 0" xyz="0 0 0.13"/>
  </joint>
  <joint name="rob1_ur_gripper_closed_fixed_joint" type="fixed">
    <parent link="rob1_real_ee_link"/>
    <child link="rob1_tcp_gripper_closed"/>
    <origin rpy="0 0 0" xyz="0 0 0.14"/>
  </joint>
  <joint name="rob1_ur_gripper_fixed_joint" type="fixed">
    <parent link="rob1_tool0"/>
    <child link="rob1_robotiq_arg2f_base_link"/>
    <origin rpy="0 0 -1.570795" xyz="0 0 0.008"/>
  </joint>
  <!-- 
    <xacro:if value="$(arg realsense_enabled)">

       <link name="realsense_base_link" />

       <joint name="realsense_mount_fixed_joint" type="fixed">
          <parent link="${prefix}real_ee_link"/>
          <child link="realsense_base_link"/>
          <origin xyz="0 0.045 0.040" rpy="0 0 ${M_PI/2}"/>
       </joint>

        <xacro:sensor_d435 parent="realsense_base_link" name="sensor_d435" >
          <origin xyz="0 0 0" rpy="0 0 0"/>
        </xacro:sensor_d435>
    </xacro:if> -->
  <joint name="rob1_real_ELP_link" type="fixed">
    <parent link="rob1_real_ee_link"/>
    <child link="rob1_ELP_CAM"/>
    <origin rpy="0.0 0.0 0" xyz="0 0.045 0.03"/>
  </joint>
  <link name="rob1_ELP_CAM">
    <visual>
      <origin rpy="0 0 0" xyz="0 0 0.05"/>
      <geometry>
        <box size="0.13 0.04 0.06"/>
      </geometry>
      <material name="rob1_ELP_CAM">
        <color rgba="0.102 0.000 0.102 1.0"/>
      </material>
    </visual>
    <collision>
      <origin rpy="0 0 0" xyz="0 0 0.04"/>
      <geometry>
        <box size="0.13 0.05 0.06"/>
      </geometry>
    </collision>
  </link>
  <joint name="rob1_safety_link" type="fixed">
    <parent link="rob1_real_ee_link"/>
    <child link="rob1_safety_zone"/>
    <origin rpy="0.0 0.0 0" xyz="0 0 0.05"/>
  </joint>
  <link name="rob1_safety_zone">
    <visual>
      <origin rpy="0 0 0" xyz="0 0 0"/>
      <geometry>
        <cylinder length="0.100" radius="0.045"/>
      </geometry>
      <material name="{prefix}safety_zone">
        <color rgba="0.192 0.192 0.192 1.0"/>
      </material>
    </visual>
    <collision>
      <origin rpy="0 0 0" xyz="0 0 0"/>
      <geometry>
        <cylinder length="0.100" radius="0.045"/>
      </geometry>
    </collision>
  </link>
  <joint name="rob1_safety_box1_link" type="fixed">
    <!-- <parent link="${prefix}safety_zone" /> -->
    <parent link="rob1_right_inner_finger_pad"/>
    <child link="rob1_safety_box1_zone"/>
    <origin rpy="0.0 0.0 0" xyz="0.0 0 0.0"/>
  </joint>
  <link name="rob1_safety_box1_zone">
    <visual>
      <origin rpy="0 0 0" xyz="0 0.02 0"/>
      <geometry>
        <box size="0.05 0.02 0.08"/>
      </geometry>
      <material name="{prefix}safety_box1_zone">
        <color rgba="0.002 0.192 0.192 0.5"/>
      </material>
    </visual>
    <collision>
      <origin rpy="0 0 0" xyz="0 0.02 0"/>
      <geometry>
        <box size="0.05 0.04 0.01"/>
      </geometry>
    </collision>
  </link>
  <joint name="rob1_safety_box2_link" type="fixed">
    <!-- <parent link="${prefix}safety_zone" /> -->
    <parent link="rob1_left_inner_finger_pad"/>
    <child link="rob1_safety_box2_zone"/>
    <origin rpy="0.0 0.0 0" xyz="0.00 0 0.0"/>
  </joint>
  <link name="rob1_safety_box2_zone">
    <visual>
      <origin rpy="0 0 0" xyz="0 0.02 0"/>
      <geometry>
        <box size="0.05 0.02 0.08"/>
      </geometry>
      <material name="{prefix}safety_box2_zone">
        <color rgba="0.002 0.192 0.192 0.5"/>
      </material>
    </visual>
    <collision>
      <origin rpy="0 0 0" xyz="0 0.02 0"/>
      <geometry>
        <box size="0.05 0.04 0.01"/>
      </geometry>
    </collision>
  </link>
  <gazebo>
    <plugin filename="libgazebo_ros_control.so" name="ros_control">
      <!--robotNamespace>/</robotNamespace-->
      <!--robotSimType>gazebo_ros_control/DefaultRobotHWSim</robotSimType-->
    </plugin>
    <!--
    <plugin name="gazebo_ros_power_monitor_controller" filename="libgazebo_ros_power_monitor.so">
      <alwaysOn>true</alwaysOn>
      <updateRate>1.0</updateRate>
      <timeout>5</timeout>
      <powerStateTopic>power_state</powerStateTopic>
      <powerStateRate>10.0</powerStateRate>
      <fullChargeCapacity>87.78</fullChargeCapacity>     
      <dischargeRate>-474</dischargeRate>
      <chargeRate>525</chargeRate>
      <dischargeVoltage>15.52</dischargeVoltage>
      <chargeVoltage>16.41</chargeVoltage>
    </plugin>
-->
  </gazebo>
  <!-- realsense d435 -->
  <!--   <xacro:include filename="$(find realsense2_description)/urdf/_d435.urdf.xacro" /> -->
  <!-- measured from model -->
  <!-- link lengths used in model -->
  <!-- manually measured -->
  <link name="rob2_base_link">
    <visual>
      <origin rpy="0 0 3.14159265359" xyz="0 0 0"/>
      <geometry>
        <mesh filename="package://ur_e_description/meshes/ur5e/visual/base.dae"/>
      </geometry>
      <material name="LightGrey">
        <color rgba="0.7 0.7 0.7 1.0"/>
      </material>
    </visual>
    <collision>
      <origin rpy="0 0 3.14159265359" xyz="0 0 0"/>
      <geometry>
        <mesh filename="package://ur_e_description/meshes/ur5e/collision/base.stl"/>
      </geometry>
    </collision>
    <inertial>
      <mass value="4.0"/>
      <origin rpy="0 0 0" xyz="0.0 0.0 0.0"/>
      <inertia ixx="0.00443333156" ixy="0.0" ixz="0.0" iyy="0.00443333156" iyz="0.0" izz="0.0072"/>
    </inertial>
  </link>
  <joint name="rob2_shoulder_pan_joint" type="revolute">
    <parent link="rob2_base_link"/>
    <child link="rob2_shoulder_link"/>
    <origin rpy="0 0 3.14159265359" xyz="0 0 0.1625"/>
    <axis xyz="0 0 1"/>
    <limit effort="150.0" lower="-6.28318530718" upper="6.28318530718" velocity="3.14"/>
    <dynamics damping="0.0" friction="0.0"/>
  </joint>
  <link name="rob2_shoulder_link">
    <visual>
      <origin rpy="0 0 3.14159265359" xyz="0 0 0"/>
      <geometry>
        <mesh filename="package://ur_e_description/meshes/ur5e/visual/shoulder.dae"/>
      </geometry>
      <material name="LightGrey">
        <color rgba="0.7 0.7 0.7 1.0"/>
      </material>
    </visual>
    <collision>
      <origin rpy="0 0 3.14159265359" xyz="0 0 0"/>
      <geometry>
        <mesh filename="package://ur_e_description/meshes/ur5e/collision/shoulder.stl"/>
      </geometry>
    </collision>
    <inertial>
      <mass value="3.7"/>
      <origin rpy="0 0 0" xyz="0.0 0.0 0.0"/>
      <inertia ixx="0.010267495893" ixy="0.0" ixz="0.0" iyy="0.010267495893" iyz="0.0" izz="0.00666"/>
    </inertial>
  </link>
  <joint name="rob2_shoulder_lift_joint" type="revolute">
    <parent link="rob2_shoulder_link"/>
    <child link="rob2_upper_arm_link"/>
    <origin rpy="1.570796327 0 0" xyz="0 0 0"/>
    <axis xyz="0 0 1"/>
    <limit effort="150.0" lower="-6.28318530718" upper="6.28318530718" velocity="3.14"/>
    <dynamics damping="0.0" friction="0.0"/>
  </joint>
  <link name="rob2_upper_arm_link">
    <visual>
      <origin rpy="1.57079632679 0 -1.57079632679" xyz="0 0 0.138"/>
      <geometry>
        <mesh filename="package://ur_e_description/meshes/ur5e/visual/upperarm.dae"/>
      </geometry>
      <material name="LightGrey">
        <color rgba="0.7 0.7 0.7 1.0"/>
      </material>
    </visual>
    <collision>
      <origin rpy="1.57079632679 0 -1.57079632679" xyz="0 0 0.138"/>
      <geometry>
        <mesh filename="package://ur_e_description/meshes/ur5e/collision/upperarm.stl"/>
      </geometry>
    </collision>
    <inertial>
      <mass value="8.393"/>
      <origin rpy="0 1.57079632679 0" xyz="-0.2125 0.0 0.138"/>
      <inertia ixx="0.138134736413" ixy="0.0" ixz="0.0" iyy="0.138134736413" iyz="0.0" izz="0.0236053125"/>
    </inertial>
  </link>
  <joint name="rob2_elbow_joint" type="revolute">
    <parent link="rob2_upper_arm_link"/>
    <child link="rob2_forearm_link"/>
    <origin rpy="0 0 0" xyz="-0.425 0 0"/>
    <axis xyz="0 0 1"/>
    <limit effort="150.0" lower="-3.14159265359" upper="3.14159265359" velocity="3.14"/>
    <dynamics damping="0.0" friction="0.0"/>
  </joint>
  <link name="rob2_forearm_link">
    <visual>
      <origin rpy="1.57079632679 0 -1.57079632679" xyz="0 0 0.007"/>
      <geometry>
        <mesh filename="package://ur_e_description/meshes/ur5e/visual/forearm.dae"/>
      </geometry>
      <material name="LightGrey">
        <color rgba="0.7 0.7 0.7 1.0"/>
      </material>
    </visual>
    <collision>
      <origin rpy="1.57079632679 0 -1.57079632679" xyz="0 0 0.007"/>
      <geometry>
        <mesh filename="package://ur_e_description/meshes/ur5e/collision/forearm.stl"/>
      </geometry>
    </collision>
    <inertial>
      <mass value="2.275"/>
      <origin rpy="0 1.57079632679 0" xyz="-0.2125 0.0 0.007"/>
      <inertia ixx="0.0323610733889" ixy="0.0" ixz="0.0" iyy="0.0323610733889" iyz="0.0" izz="0.0063984375"/>
    </inertial>
  </link>
  <joint name="rob2_wrist_1_joint" type="revolute">
    <parent link="rob2_forearm_link"/>
    <child link="rob2_wrist_1_link"/>
    <origin rpy="0 0 0" xyz="-0.3922 0 0.1333"/>
    <axis xyz="0 0 1"/>
    <limit effort="28.0" lower="-6.28318530718" upper="6.28318530718" velocity="6.28"/>
    <dynamics damping="0.0" friction="0.0"/>
  </joint>
  <link name="rob2_wrist_1_link">
    <visual>
      <origin rpy="1.57079632679 0 0" xyz="0 0 -0.127"/>
      <geometry>
        <mesh filename="package://ur_e_description/meshes/ur5e/visual/wrist1.dae"/>
      </geometry>
      <material name="LightGrey">
        <color rgba="0.7 0.7 0.7 1.0"/>
      </material>
    </visual>
    <collision>
      <origin rpy="1.57079632679 0 0" xyz="0 0 -0.127"/>
      <geometry>
        <mesh filename="package://ur_e_description/meshes/ur5e/collision/wrist1.stl"/>
      </geometry>
    </collision>
    <inertial>
      <mass value="1.219"/>
      <origin rpy="0 0 0" xyz="0.0 0.0 0.0"/>
      <inertia ixx="0.00272396513625" ixy="0.0" ixz="0.0" iyy="0.00272396513625" iyz="0.0" izz="0.0034284375"/>
    </inertial>
  </link>
  <joint name="rob2_wrist_2_joint" type="revolute">
    <parent link="rob2_wrist_1_link"/>
    <child link="rob2_wrist_2_link"/>
    <origin rpy="1.570796327 0 0" xyz="0 -0.0997 -2.0448811823e-11"/>
    <axis xyz="0 0 1"/>
    <limit effort="28.0" lower="-6.28318530718" upper="6.28318530718" velocity="6.28"/>
    <dynamics damping="0.0" friction="0.0"/>
  </joint>
  <link name="rob2_wrist_2_link">
    <visual>
      <origin rpy="0 0 0" xyz="0 0 -0.0997"/>
      <geometry>
        <mesh filename="package://ur_e_description/meshes/ur5e/visual/wrist2.dae"/>
      </geometry>
      <material name="LightGrey">
        <color rgba="0.7 0.7 0.7 1.0"/>
      </material>
    </visual>
    <collision>
      <origin rpy="0 0 0" xyz="0 0 -0.0997"/>
      <geometry>
        <mesh filename="package://ur_e_description/meshes/ur5e/collision/wrist2.stl"/>
      </geometry>
    </collision>
    <inertial>
      <mass value="1.219"/>
      <origin rpy="0 0 0" xyz="0.0 0.0 0.0"/>
      <inertia ixx="0.00272194058122" ixy="0.0" ixz="0.0" iyy="0.00272194058122" iyz="0.0" izz="0.0034284375"/>
    </inertial>
  </link>
  <joint name="rob2_wrist_3_joint" type="revolute">
    <parent link="rob2_wrist_2_link"/>
    <child link="rob2_wrist_3_link"/>
    <origin rpy="1.57079632659 3.14159265359 3.14159265359" xyz="0 0.0996 -2.04283014801e-11"/>
    <axis xyz="0 0 1"/>
    <limit effort="28.0" lower="-6.28318530718" upper="6.28318530718" velocity="6.28"/>
    <dynamics damping="0.0" friction="0.0"/>
  </joint>
  <link name="rob2_wrist_3_link">
    <visual>
      <origin rpy="1.57079632679 0 0" xyz="0 0 -0.0989"/>
      <geometry>
        <mesh filename="package://ur_e_description/meshes/ur5e/visual/wrist3.dae"/>
      </geometry>
      <material name="LightGrey">
        <color rgba="0.7 0.7 0.7 1.0"/>
      </material>
    </visual>
    <collision>
      <origin rpy="1.57079632679 0 0" xyz="0 0 -0.0989"/>
      <geometry>
        <mesh filename="package://ur_e_description/meshes/ur5e/collision/wrist3.stl"/>
      </geometry>
    </collision>
    <inertial>
      <mass value="0.1879"/>
      <origin rpy="0 0 0" xyz="0.0 0.0 -0.025"/>
      <inertia ixx="0.000134270154625" ixy="0.0" ixz="0.0" iyy="0.000134270154625" iyz="0.0" izz="0.00019024875"/>
    </inertial>
  </link>
  <joint name="rob2_ee_fixed_joint" type="fixed">
    <parent link="rob2_wrist_3_link"/>
    <child link="rob2_ee_link"/>
    <origin rpy="0.0 -1.57079632679 1.57079632679" xyz="0.0 0.0 0.0"/>
  </joint>
  <link name="rob2_ee_link">
    <collision>
      <geometry>
        <box size="0.01 0.01 0.01"/>
      </geometry>
      <origin rpy="0 0 0" xyz="-0.01 0 0"/>
    </collision>
  </link>
  <transmission name="rob2_shoulder_pan_trans">
    <type>transmission_interface/SimpleTransmission</type>
    <joint name="rob2_shoulder_pan_joint">
      <hardwareInterface>hardware_interface/PositionJointInterface</hardwareInterface>
    </joint>
    <actuator name="rob2_shoulder_pan_motor">
      <mechanicalReduction>1</mechanicalReduction>
    </actuator>
  </transmission>
  <transmission name="rob2_shoulder_lift_trans">
    <type>transmission_interface/SimpleTransmission</type>
    <joint name="rob2_shoulder_lift_joint">
      <hardwareInterface>hardware_interface/PositionJointInterface</hardwareInterface>
    </joint>
    <actuator name="rob2_shoulder_lift_motor">
      <mechanicalReduction>1</mechanicalReduction>
    </actuator>
  </transmission>
  <transmission name="rob2_elbow_trans">
    <type>transmission_interface/SimpleTransmission</type>
    <joint name="rob2_elbow_joint">
      <hardwareInterface>hardware_interface/PositionJointInterface</hardwareInterface>
    </joint>
    <actuator name="rob2_elbow_motor">
      <mechanicalReduction>1</mechanicalReduction>
    </actuator>
  </transmission>
  <transmission name="rob2_wrist_1_trans">
    <type>transmission_interface/SimpleTransmission</type>
    <joint name="rob2_wrist_1_joint">
      <hardwareInterface>hardware_interface/PositionJointInterface</hardwareInterface>
    </joint>
    <actuator name="rob2_wrist_1_motor">
      <mechanicalReduction>1</mechanicalReduction>
    </actuator>
  </transmission>
  <transmission name="rob2_wrist_2_trans">
    <type>transmission_interface/SimpleTransmission</type>
    <joint name="rob2_wrist_2_joint">
      <hardwareInterface>hardware_interface/PositionJointInterface</hardwareInterface>
    </joint>
    <actuator name="rob2_wrist_2_motor">
      <mechanicalReduction>1</mechanicalReduction>
    </actuator>
  </transmission>
  <transmission name="rob2_wrist_3_trans">
    <type>transmission_interface/SimpleTransmission</type>
    <joint name="rob2_wrist_3_joint">
      <hardwareInterface>hardware_interface/PositionJointInterface</hardwareInterface>
    </joint>
    <actuator name="rob2_wrist_3_motor">
      <mechanicalReduction>1</mechanicalReduction>
    </actuator>
  </transmission>
  <gazebo reference="rob2_shoulder_link">
    <selfCollide>true</selfCollide>
  </gazebo>
  <gazebo reference="rob2_upper_arm_link">
    <selfCollide>true</selfCollide>
  </gazebo>
  <gazebo reference="rob2_forearm_link">
    <selfCollide>true</selfCollide>
  </gazebo>
  <gazebo reference="rob2_wrist_1_link">
    <selfCollide>true</selfCollide>
  </gazebo>
  <gazebo reference="rob2_wrist_3_link">
    <selfCollide>true</selfCollide>
  </gazebo>
  <gazebo reference="rob2_wrist_2_link">
    <selfCollide>true</selfCollide>
  </gazebo>
  <gazebo reference="rob2_ee_link">
    <selfCollide>true</selfCollide>
  </gazebo>
  <!-- ROS base_link to UR 'Base' Coordinates transform -->
  <link name="rob2_base"/>
  <joint name="rob2_base_link-base_fixed_joint" type="fixed">
    <!-- NOTE: this rotation is only needed as long as base_link itself is
                 not corrected wrt the real robot (ie: rotated over 180
                 degrees)
      -->
    <origin rpy="0 0 -3.14159265359" xyz="0 0 0"/>
    <parent link="rob2_base_link"/>
    <child link="rob2_base"/>
  </joint>
  <!-- Frame coincident with all-zeros TCP on UR controller -->
  <link name="rob2_tool0"/>
  <joint name="rob2_wrist_3_link-tool0_fixed_joint" type="fixed">
    <origin rpy="0 0 0" xyz="0 0 0"/>
    <parent link="rob2_wrist_3_link"/>
    <child link="rob2_tool0"/>
  </joint>
  <link name="rob2_robotiq_arg2f_base_link">
    <inertial>
      <origin rpy="0 0 0" xyz="8.625E-08 -4.6583E-06 0.03145"/>
      <mass value="0.22652"/>
      <inertia ixx="0.00020005" ixy="-4.2442E-10" ixz="-2.9069E-10" iyy="0.00017832" iyz="-3.4402E-08" izz="0.00013478"/>
    </inertial>
    <visual>
      <origin rpy="0 0 0" xyz="0 0 0"/>
      <geometry>
        <mesh filename="package://robotiq_2f_85_gripper_visualization/meshes/visual/robotiq_arg2f_85_base_link.dae" scale="0.001 0.001 0.001"/>
      </geometry>
      <material name="">
        <color rgba="0.1 0.1 0.1 1"/>
      </material>
    </visual>
    <collision>
      <origin rpy="0 0 0" xyz="0 0 0"/>
      <geometry>
        <mesh filename="package://robotiq_2f_85_gripper_visualization/meshes/collision/robotiq_arg2f_base_link.stl"/>
      </geometry>
    </collision>
  </link>
  <link name="rob2_left_outer_knuckle">
    <!--<inertial>
        <origin xyz="-0.000200000000003065 0.0199435877845359 0.0292245259211331" rpy="0 0 0" />
        <mass value="0.00853198276973456" />
        <inertia ixx="2.89328108496468E-06" ixy="-1.57935047237397E-19" ixz="-1.93980378593255E-19" iyy="1.86719750325683E-06" iyz="-1.21858577871576E-06" izz="1.21905238907251E-06" />
        </inertial> -->
    <visual>
      <origin rpy="0 0 0" xyz="0 0 0"/>
      <geometry>
        <mesh filename="package://robotiq_2f_85_gripper_visualization/meshes/visual/robotiq_arg2f_85_outer_knuckle.dae" scale="0.001 0.001 0.001"/>
      </geometry>
      <material name="">
        <color rgba="0.792156862745098 0.819607843137255 0.933333333333333 1"/>
      </material>
    </visual>
    <collision>
      <origin rpy="0 0 0" xyz="0 0 0"/>
      <geometry>
        <mesh filename="package://robotiq_2f_85_gripper_visualization/meshes/collision/robotiq_arg2f_85_outer_knuckle.dae" scale="0.001 0.001 0.001"/>
      </geometry>
    </collision>
  </link>
  <link name="rob2_left_outer_finger">
    <!--<inertial>
        <origin xyz="0.00030115855001899 0.0373907951953854 -0.0208027427000385" rpy="0 0 0" />
        <mass value="0.022614240507152" />
        <inertia ixx="1.52518312458174E-05" ixy="9.76583423954399E-10" ixz="-5.43838577022588E-10" iyy="6.17694243867776E-06" iyz="6.78636130740228E-06" izz="1.16494917907219E-05" />
        </inertial> -->
    <visual>
      <origin rpy="0 0 0" xyz="0 0 0"/>
      <geometry>
        <mesh filename="package://robotiq_2f_85_gripper_visualization/meshes/visual/robotiq_arg2f_85_outer_finger.dae" scale="0.001 0.001 0.001"/>
      </geometry>
      <material name="">
        <color rgba="0.1 0.1 0.1 1"/>
      </material>
    </visual>
    <collision>
      <origin rpy="0 0 0" xyz="0 0 0"/>
      <geometry>
        <mesh filename="package://robotiq_2f_85_gripper_visualization/meshes/collision/robotiq_arg2f_85_outer_finger.dae" scale="0.001 0.001 0.001"/>
      </geometry>
    </collision>
  </link>
  <link name="rob2_left_inner_finger">
    <!--<inertial>
        <origin xyz="0.000299999999999317 0.0160078233491243 -0.0136945669206257" rpy="0 0 0" />
        <mass value="0.0104003125914103" />
        <inertia ixx="2.71909453810972E-06" ixy="1.35402465472579E-21" ixz="-7.1817349065269E-22" iyy="7.69100314106116E-07" iyz="6.74715432769696E-07" izz="2.30315190420171E-06" />
        </inertial> -->
    <visual>
      <origin rpy="0 0 0" xyz="0 0 0"/>
      <geometry>
        <mesh filename="package://robotiq_2f_85_gripper_visualization/meshes/visual/robotiq_arg2f_85_inner_finger.dae" scale="0.001 0.001 0.001"/>
      </geometry>
      <material name="">
        <color rgba="0.1 0.1 0.1 1"/>
      </material>
    </visual>
    <collision>
      <origin rpy="0 0 0" xyz="0 0 0"/>
      <geometry>
        <mesh filename="package://robotiq_2f_85_gripper_visualization/meshes/collision/robotiq_arg2f_85_inner_finger.dae" scale="0.001 0.001 0.001"/>
      </geometry>
    </collision>
  </link>
  <link name="rob2_left_inner_finger_pad">
    <visual>
      <origin rpy="0 0 0" xyz="0 0 0.005"/>
      <geometry>
        <box size="0.022 0.00635 0.0375"/>
      </geometry>
      <material name="">
        <color rgba="0.9 0.9 0.9 1"/>
      </material>
    </visual>
    <collision>
      <origin rpy="0 0 0" xyz="0 0 0.005"/>
      <geometry>
        <box size="0.022 0.00635 0.0375"/>
      </geometry>
      <material name="">
        <color rgba="0.9 0.0 0.0 1"/>
      </material>
    </collision>
  </link>
  <link name="rob2_left_inner_knuckle">
    <!--<inertial>
        <origin xyz="0.000123011831763771 0.0507850843201817 0.00103968640075166" rpy="0 0 0" />
       <mass value="0.0271177346495152" />
        <inertia ixx="2.61910379223783E-05" ixy="-2.43616858946494E-07" ixz="-6.37789906117123E-09" iyy="2.8270243746167E-06" iyz="-5.37200748039765E-07" izz="2.83695868220296E-05" />
        </inertial> -->
    <visual>
      <origin rpy="0 0 0" xyz="0 0 0"/>
      <geometry>
        <mesh filename="package://robotiq_2f_85_gripper_visualization/meshes/visual/robotiq_arg2f_85_inner_knuckle.dae" scale="0.001 0.001 0.001"/>
      </geometry>
      <material name="">
        <color rgba="0.1 0.1 0.1 1"/>
      </material>
    </visual>
    <collision>
      <origin rpy="0 0 0" xyz="0 0 0"/>
      <geometry>
        <mesh filename="package://robotiq_2f_85_gripper_visualization/meshes/collision/robotiq_arg2f_85_inner_knuckle.dae" scale="0.001 0.001 0.001"/>
      </geometry>
    </collision>
  </link>
  <link name="rob2_right_outer_knuckle">
    <!--<inertial>
        <origin xyz="-0.000200000000003065 0.0199435877845359 0.0292245259211331" rpy="0 0 0" />
        <mass value="0.00853198276973456" />
        <inertia ixx="2.89328108496468E-06" ixy="-1.57935047237397E-19" ixz="-1.93980378593255E-19" iyy="1.86719750325683E-06" iyz="-1.21858577871576E-06" izz="1.21905238907251E-06" />
        </inertial> -->
    <visual>
      <origin rpy="0 0 0" xyz="0 0 0"/>
      <geometry>
        <mesh filename="package://robotiq_2f_85_gripper_visualization/meshes/visual/robotiq_arg2f_85_outer_knuckle.dae" scale="0.001 0.001 0.001"/>
      </geometry>
      <material name="">
        <color rgba="0.792156862745098 0.819607843137255 0.933333333333333 1"/>
      </material>
    </visual>
    <collision>
      <origin rpy="0 0 0" xyz="0 0 0"/>
      <geometry>
        <mesh filename="package://robotiq_2f_85_gripper_visualization/meshes/collision/robotiq_arg2f_85_outer_knuckle.dae" scale="0.001 0.001 0.001"/>
      </geometry>
    </collision>
  </link>
  <link name="rob2_right_outer_finger">
    <!--<inertial>
        <origin xyz="0.00030115855001899 0.0373907951953854 -0.0208027427000385" rpy="0 0 0" />
        <mass value="0.022614240507152" />
        <inertia ixx="1.52518312458174E-05" ixy="9.76583423954399E-10" ixz="-5.43838577022588E-10" iyy="6.17694243867776E-06" iyz="6.78636130740228E-06" izz="1.16494917907219E-05" />
        </inertial> -->
    <visual>
      <origin rpy="0 0 0" xyz="0 0 0"/>
      <geometry>
        <mesh filename="package://robotiq_2f_85_gripper_visualization/meshes/visual/robotiq_arg2f_85_outer_finger.dae" scale="0.001 0.001 0.001"/>
      </geometry>
      <material name="">
        <color rgba="0.1 0.1 0.1 1"/>
      </material>
    </visual>
    <collision>
      <origin rpy="0 0 0" xyz="0 0 0"/>
      <geometry>
        <mesh filename="package://robotiq_2f_85_gripper_visualization/meshes/collision/robotiq_arg2f_85_outer_finger.dae" scale="0.001 0.001 0.001"/>
      </geometry>
    </collision>
  </link>
  <link name="rob2_right_inner_finger">
    <!--<inertial>
        <origin xyz="0.000299999999999317 0.0160078233491243 -0.0136945669206257" rpy="0 0 0" />
        <mass value="0.0104003125914103" />
        <inertia ixx="2.71909453810972E-06" ixy="1.35402465472579E-21" ixz="-7.1817349065269E-22" iyy="7.69100314106116E-07" iyz="6.74715432769696E-07" izz="2.30315190420171E-06" />
        </inertial> -->
    <visual>
      <origin rpy="0 0 0" xyz="0 0 0"/>
      <geometry>
        <mesh filename="package://robotiq_2f_85_gripper_visualization/meshes/visual/robotiq_arg2f_85_inner_finger.dae" scale="0.001 0.001 0.001"/>
      </geometry>
      <material name="">
        <color rgba="0.1 0.1 0.1 1"/>
      </material>
    </visual>
    <collision>
      <origin rpy="0 0 0" xyz="0 0 0"/>
      <geometry>
        <mesh filename="package://robotiq_2f_85_gripper_visualization/meshes/collision/robotiq_arg2f_85_inner_finger.dae" scale="0.001 0.001 0.001"/>
      </geometry>
    </collision>
  </link>
  <link name="rob2_right_inner_finger_pad">
    <visual>
      <origin rpy="0 0 0" xyz="0 0 0.005"/>
      <geometry>
        <box size="0.022 0.00635 0.0375"/>
      </geometry>
      <material name="">
        <color rgba="0.9 0.9 0.9 1"/>
      </material>
    </visual>
    <collision>
      <origin rpy="0 0 0" xyz="0 0 0.005"/>
      <geometry>
        <box size="0.022 0.00635 0.0375"/>
      </geometry>
      <material name="">
        <color rgba="0.9 0.0 0.0 1"/>
      </material>
    </collision>
  </link>
  <link name="rob2_right_inner_knuckle">
    <!--<inertial>
        <origin xyz="0.000123011831763771 0.0507850843201817 0.00103968640075166" rpy="0 0 0" />
       <mass value="0.0271177346495152" />
        <inertia ixx="2.61910379223783E-05" ixy="-2.43616858946494E-07" ixz="-6.37789906117123E-09" iyy="2.8270243746167E-06" iyz="-5.37200748039765E-07" izz="2.83695868220296E-05" />
        </inertial> -->
    <visual>
      <origin rpy="0 0 0" xyz="0 0 0"/>
      <geometry>
        <mesh filename="package://robotiq_2f_85_gripper_visualization/meshes/visual/robotiq_arg2f_85_inner_knuckle.dae" scale="0.001 0.001 0.001"/>
      </geometry>
      <material name="">
        <color rgba="0.1 0.1 0.1 1"/>
      </material>
    </visual>
    <collision>
      <origin rpy="0 0 0" xyz="0 0 0"/>
      <geometry>
        <mesh filename="package://robotiq_2f_85_gripper_visualization/meshes/collision/robotiq_arg2f_85_inner_knuckle.dae" scale="0.001 0.001 0.001"/>
      </geometry>
    </collision>
  </link>
  <joint name="rob2_finger_joint" type="revolute">
    <origin rpy="0 0 3.14159265359" xyz="0 -0.0306011 0.054904"/>
    <parent link="rob2_robotiq_arg2f_base_link"/>
    <child link="rob2_left_outer_knuckle"/>
    <axis xyz="1 0 0"/>
    <limit effort="1000" lower="0" upper="0.8" velocity="2.0"/>
  </joint>
  <joint name="rob2_left_outer_finger_joint" type="fixed">
    <origin rpy="0 0 0" xyz="0 0.0315 -0.0041"/>
    <parent link="rob2_left_outer_knuckle"/>
    <child link="rob2_left_outer_finger"/>
    <axis xyz="1 0 0"/>
  </joint>
  <joint name="rob2_left_inner_knuckle_joint" type="revolute">
    <!-- <origin xyz="0 ${reflect * -0.0127} 0.06142" rpy="${pi / 2 + .725} 0 ${(reflect - 1) * pi / 2}" /> -->
    <origin rpy="0 0 3.14159265359" xyz="0 -0.0127 0.06142"/>
    <parent link="rob2_robotiq_arg2f_base_link"/>
    <child link="rob2_left_inner_knuckle"/>
    <axis xyz="1 0 0"/>
    <limit effort="1000" lower="0" upper="0.8757" velocity="2.0"/>
    <mimic joint="rob2_finger_joint" multiplier="1" offset="0"/>
  </joint>
  <joint name="rob2_left_inner_finger_joint" type="revolute">
    <origin rpy="0 0 0" xyz="0 0.0061 0.0471"/>
    <parent link="rob2_left_outer_finger"/>
    <child link="rob2_left_inner_finger"/>
    <axis xyz="1 0 0"/>
    <limit effort="1000" lower="0" upper="0.8757" velocity="2.0"/>
    <mimic joint="rob2_finger_joint" multiplier="-1" offset="0"/>
  </joint>
  <joint name="rob2_left_inner_finger_pad_joint" type="fixed">
    <origin rpy="0 0 0" xyz="0 -0.0220203446692936 0.03242"/>
    <parent link="rob2_left_inner_finger"/>
    <child link="rob2_left_inner_finger_pad"/>
    <axis xyz="0 0 1"/>
  </joint>
  <joint name="rob2_right_outer_knuckle_joint" type="revolute">
    <origin rpy="0 0 0" xyz="0 0.0306011 0.054904"/>
    <parent link="rob2_robotiq_arg2f_base_link"/>
    <child link="rob2_right_outer_knuckle"/>
    <axis xyz="1 0 0"/>
    <limit effort="1000" lower="0" upper="0.81" velocity="2.0"/>
    <mimic joint="rob2_finger_joint" multiplier="1" offset="0"/>
  </joint>
  <joint name="rob2_right_outer_finger_joint" type="fixed">
    <origin rpy="0 0 0" xyz="0 0.0315 -0.0041"/>
    <parent link="rob2_right_outer_knuckle"/>
    <child link="rob2_right_outer_finger"/>
    <axis xyz="1 0 0"/>
  </joint>
  <joint name="rob2_right_inner_knuckle_joint" type="revolute">
    <!-- <origin xyz="0 ${reflect * -0.0127} 0.06142" rpy="${pi / 2 + .725} 0 ${(reflect - 1) * pi / 2}" /> -->
    <origin rpy="0 0 0.0" xyz="0 0.0127 0.06142"/>
    <parent link="rob2_robotiq_arg2f_base_link"/>
    <child link="rob2_right_inner_knuckle"/>
    <axis xyz="1 0 0"/>
    <limit effort="1000" lower="0" upper="0.8757" velocity="2.0"/>
    <mimic joint="rob2_finger_joint" multiplier="1" offset="0"/>
  </joint>
  <joint name="rob2_right_inner_finger_joint" type="revolute">
    <origin rpy="0 0 0" xyz="0 0.0061 0.0471"/>
    <parent link="rob2_right_outer_finger"/>
    <child link="rob2_right_inner_finger"/>
    <axis xyz="1 0 0"/>
    <limit effort="1000" lower="0" upper="0.8757" velocity="2.0"/>
    <mimic joint="rob2_finger_joint" multiplier="-1" offset="0"/>
  </joint>
  <joint name="rob2_right_inner_finger_pad_joint" type="fixed">
    <origin rpy="0 0 0" xyz="0 -0.0220203446692936 0.03242"/>
    <parent link="rob2_right_inner_finger"/>
    <child link="rob2_right_inner_finger_pad"/>
    <axis xyz="0 0 1"/>
  </joint>
  <transmission name="rob2_finger_joint_trans">
    <type>transmission_interface/SimpleTransmission</type>
    <joint name="rob2_finger_joint">
      <hardwareInterface>PositionJointInterface</hardwareInterface>
    </joint>
    <actuator name="rob2_finger_joint_motor">
      <mechanicalReduction>1</mechanicalReduction>
    </actuator>
  </transmission>
  <link name="rob2_real_base_link"/>
  <joint name="rob2_real_base_joint" type="fixed">
    <parent link="rob2_real_base_link"/>
    <child link="rob2_base_link"/>
    <origin rpy="0.0 0.0 3.14159" xyz="0 0.0 0.0"/>
  </joint>
  <link name="rob2_world"/>
  <joint name="rob2_world_base_joint" type="fixed">
    <parent link="rob2_world"/>
    <child link="rob2_real_base_link"/>
    <origin rpy="0.0 0.0 0" xyz="0 0.0 0.0"/>
  </joint>
  <joint name="rob2_ur_real_ee_fixed_joint" type="fixed">
    <parent link="rob2_ee_link"/>
    <child link="rob2_real_ee_link"/>
    <origin rpy="-1.570795 0.0 -1.570795" xyz="0.0 0.0 0.0"/>
  </joint>
  <link name="rob2_real_ee_link"/>
  <!-- for grasp point -->
  <link name="rob2_tcp_gripper_open"/>
  <link name="rob2_tcp_gripper_closed"/>
  <joint name="rob2_ur_tcp_fixed_joint" type="fixed">
    <parent link="rob2_real_ee_link"/>
    <child link="rob2_tcp_gripper_open"/>
    <origin rpy="0 0 0" xyz="0 0 0.13"/>
  </joint>
  <joint name="rob2_ur_gripper_closed_fixed_joint" type="fixed">
    <parent link="rob2_real_ee_link"/>
    <child link="rob2_tcp_gripper_closed"/>
    <origin rpy="0 0 0" xyz="0 0 0.14"/>
  </joint>
  <joint name="rob2_ur_gripper_fixed_joint" type="fixed">
    <parent link="rob2_tool0"/>
    <child link="rob2_robotiq_arg2f_base_link"/>
    <origin rpy="0 0 -1.570795" xyz="0 0 0.008"/>
  </joint>
  <joint name="rob2_real_ee_link" type="fixed">
    <parent link="rob2_real_ee_link"/>
    <child link="rob2_ELP_CAM"/>
    <origin rpy="0.0 0.0 0" xyz="0 0.045 0.040"/>
  </joint>
  <link name="rob2_ELP_CAM">
    <visual>
      <origin rpy="0 0 0" xyz="0 0 0.05"/>
      <geometry>
        <box size="0.13 0.05 0.06"/>
      </geometry>
      <material name="rob2_ELP_CAM">
        <color rgba="0.102 0.000 0.102 1.0"/>
      </material>
    </visual>
    <collision>
      <origin rpy="0 0 0" xyz="0 0 0.05"/>
      <geometry>
        <box size="0.13 0.05 0.06"/>
      </geometry>
    </collision>
  </link>
  <joint name="rob2_real_sense_link" type="fixed">
    <parent link="rob2_real_ee_link"/>
    <child link="rob2_sense_CAM"/>
    <origin rpy="0.0 0.0 0" xyz="0 -0.045 0.03"/>
  </joint>
  <link name="rob2_sense_CAM">
    <visual>
      <origin rpy="0 0 0" xyz="0 0 0.05"/>
      <geometry>
        <box size="0.12 0.04 0.05"/>
      </geometry>
      <material name="rob2_sense_CAM">
        <color rgba="0.102 0.000 0.102 1.0"/>
      </material>
    </visual>
    <collision>
      <origin rpy="0 0 0" xyz="0 0 0.04"/>
      <geometry>
        <box size="0.12 0.04 0.06"/>
      </geometry>
    </collision>
  </link>
  <joint name="rob2_safety_link" type="fixed">
    <parent link="rob2_real_ee_link"/>
    <child link="rob2_safety_zone"/>
    <origin rpy="0.0 0.0 0" xyz="0 0 0.05"/>
  </joint>
  <link name="rob2_safety_zone">
    <visual>
      <origin rpy="0 0 0" xyz="0 0 0"/>
      <geometry>
        <cylinder length="0.100" radius="0.045"/>
      </geometry>
      <material name="{prefix}safety_zone">
        <color rgba="0.192 0.192 0.192 1.0"/>
      </material>
    </visual>
    <collision>
      <origin rpy="0 0 0" xyz="0 0 0"/>
      <geometry>
        <cylinder length="0.100" radius="0.045"/>
      </geometry>
    </collision>
  </link>
  <joint name="rob2_safety_box1_link" type="fixed">
    <!-- <parent link="${prefix}safety_zone" /> -->
    <parent link="rob2_right_inner_finger_pad"/>
    <child link="rob2_safety_box1_zone"/>
    <origin rpy="0.0 0.0 0" xyz="0.0 0 0"/>
  </joint>
  <link name="rob2_safety_box1_zone">
    <visual>
      <origin rpy="0 0 0" xyz="0 0 0"/>
      <geometry>
        <box size="0.05 0.02 0.13"/>
      </geometry>
      <material name="{prefix}safety_box1_zone">
        <color rgba="0.002 0.192 0.192 1.0"/>
      </material>
    </visual>
    <collision>
      <origin rpy="0 0 0" xyz="0 0 0"/>
      <geometry>
        <box size="0.05 0.02 0.01"/>
      </geometry>
    </collision>
  </link>
  <joint name="rob2_safety_box2_link" type="fixed">
    <!-- <parent link="${prefix}safety_zone" /> -->
    <parent link="rob2_left_inner_finger_pad"/>
    <child link="rob2_safety_box2_zone"/>
    <origin rpy="0.0 0.0 0" xyz="0 0 0"/>
  </joint>
  <link name="rob2_safety_box2_zone">
    <visual>
      <origin rpy="0 0 0" xyz="0 0 0"/>
      <geometry>
        <box size="0.05 0.02 0.13"/>
      </geometry>
      <material name="{prefix}safety_box2_zone">
        <color rgba="0.002 0.192 0.192 1.0"/>
      </material>
    </visual>
    <collision>
      <origin rpy="0 0 0" xyz="0 0 0"/>
      <geometry>
        <box size="0.05 0.02 0.01"/>
      </geometry>
    </collision>
  </link>
  <!--     <xacro:if value="$(arg realsense_enabled)">

       <link name="${prefix}realsense_base_link" />

       <joint name="${prefix}realsense_mount_fixed_joint" type="fixed">
          <parent link="${prefix}real_ee_link"/>
          <child link="${prefix}realsense_base_link"/>
          <origin xyz="0 0.045 0.040" rpy="0 0 ${M_PI/2}"/>
       </joint>

        <xacro:sensor_d435 parent="${prefix}realsense_base_link" name="${prefix}sensor_d435" >
          <origin xyz="0 0 0" rpy="0 0 0"/>
        </xacro:sensor_d435>
    </xacro:if> -->
  <link name="bar1">
    <visual>
      <origin rpy="0 0 0" xyz="0 0 0"/>
      <geometry>
        <box size="0.03 0.03 1.5"/>
      </geometry>
      <material name="bar1">
        <color rgba="0.192 0.192 0.192 1.0"/>
      </material>
    </visual>
    <collision>
      <origin rpy="0 0 0" xyz="0 0 0"/>
      <geometry>
        <box size="0.09 0.09 1.5"/>
      </geometry>
    </collision>
  </link>
  <link name="bar2">
    <visual>
      <origin rpy="0 0 0" xyz="0 0 0"/>
      <geometry>
        <box size="0.03 0.03 1.5"/>
      </geometry>
      <material name="bar2">
        <color rgba="0.192 0.192 0.192 1.0"/>
      </material>
    </visual>
    <collision>
      <origin rpy="0 0 0" xyz="0 0 0"/>
      <geometry>
        <box size="0.09 0.09 1.5"/>
      </geometry>
    </collision>
  </link>
  <link name="bar3">
    <visual>
      <origin rpy="0 0 0" xyz="0 0 0"/>
      <geometry>
        <box size="0.03 0.03 1.5"/>
      </geometry>
      <material name="bar3">
        <color rgba="0.192 0.192 0.192 1.0"/>
      </material>
    </visual>
    <collision>
      <origin rpy="0 0 0" xyz="0 0 0"/>
      <geometry>
        <box size="0.09 0.09 1.5"/>
      </geometry>
    </collision>
  </link>
  <link name="bar4">
    <visual>
      <origin rpy="0 0 0" xyz="0 0 0"/>
      <geometry>
        <box size="0.03 0.03 1.5"/>
      </geometry>
      <material name="bar4">
        <color rgba="0.192 0.192 0.192 1.0"/>
      </material>
    </visual>
    <collision>
      <origin rpy="0 0 0" xyz="0 0 0"/>
      <geometry>
        <box size="0.09 0.09 1.5"/>
      </geometry>
    </collision>
  </link>
  <!--  <link name="table">
       <visual>
         <origin xyz="0 0 -0.4" rpy="0 0 0" />
         <geometry>
           <box size="2.3 3 0.8" />
         </geometry>
         <material name="table">
           <color rgba="0.192 0.192 0.192 1.0"/>
         </material>
       </visual>

       <collision>
         <origin xyz="0 0 -0.4" rpy="0 0 0"/>
         <geometry>
           <box size="2.3 3 0.8"/>
         </geometry>
       </collision>
     </link> -->
  <link name="table">
    <visual>
      <origin rpy="0 0 0" xyz="-0.885  0 -0.4"/>
      <geometry>
        <box size="0.57 1.98 0.8"/>
      </geometry>
      <material name="table">
        <color rgba="0.192 0.192 0.192 0.7"/>
      </material>
    </visual>
    <collision>
      <origin rpy="0 0 0" xyz="-0.885 0 -0.4"/>
      <geometry>
        <box size="0.57 1.98 0.8"/>
      </geometry>
    </collision>
  </link>
  <link name="table_station2">
    <visual>
      <origin rpy="0 0 0" xyz="0 -0.18 -0.015"/>
      <geometry>
        <box size="1.2 0.18 0.03"/>
      </geometry>
      <material name="color1">
        <color rgba="0.7 0.01 0.7 0.8"/>
      </material>
    </visual>
    <collision>
      <origin rpy="0 0 0" xyz="0 -0.18 -0.015"/>
      <geometry>
        <box size="1.2 0.18 0.03"/>
      </geometry>
    </collision>
  </link>
  <link name="table_station1">
    <visual>
      <origin rpy="0 0 0" xyz="0 0.045 -0.015"/>
      <geometry>
        <box size="1.2 0.27 0.03"/>
      </geometry>
      <material name="color2">
        <color rgba="0.1 0.7 0.1 0.8"/>
      </material>
    </visual>
    <collision>
      <origin rpy="0 0 0" xyz="0 0.045 -0.015"/>
      <geometry>
        <box size="1.2 0.27 0.03"/>
      </geometry>
    </collision>
  </link>
  <link name="table_link1">
    <visual>
      <origin rpy="0 0 0" xyz="0 -0.630 -0.4"/>
      <geometry>
        <box size="1.2 0.72 0.8"/>
      </geometry>
      <material name="table">
        <color rgba="0.192 0.192 0.192 1.0"/>
      </material>
    </visual>
    <collision>
      <origin rpy="0 0 0" xyz="0 -0.630 -0.4"/>
      <geometry>
        <box size="1.2 0.72 0.8"/>
      </geometry>
    </collision>
  </link>
  <link name="table_link2">
    <visual>
      <origin rpy="0 0 0" xyz="0 0.585 -0.4"/>
      <geometry>
        <box size="1.2 0.81 0.8"/>
      </geometry>
      <material name="table">
        <color rgba="0.192 0.192 0.192 1.0"/>
      </material>
    </visual>
    <collision>
      <origin rpy="0 0 0" xyz="0 0.585 -0.4"/>
      <geometry>
        <box size="1.2 0.81 0.8"/>
      </geometry>
    </collision>
  </link>
  <link name="ceiling">
    <visual>
      <origin rpy="0 0 0" xyz="0 0 0.0005"/>
      <geometry>
        <box size="2.3 3 0.001"/>
      </geometry>
      <material name="ceiling">
        <color rgba="0.192 0.192 0.192 1.0"/>
      </material>
    </visual>
    <collision>
      <origin rpy="0 0 0" xyz="0 0 0.0005"/>
      <geometry>
        <box size="2.3 3 0.001"/>
      </geometry>
    </collision>
  </link>
  <joint name="table_bar1" type="fixed">
    <parent link="table"/>
    <child link="bar1"/>
    <origin rpy="0.0 0.0 0" xyz="0.990 0.985 0.75"/>
  </joint>
  <joint name="table_bar2" type="fixed">
    <parent link="table"/>
    <child link="bar2"/>
    <origin rpy="0.0 0.0 0" xyz="-1.125 0.985 0.75"/>
  </joint>
  <joint name="table_bar3" type="fixed">
    <parent link="table"/>
    <child link="bar3"/>
    <origin rpy="0.0 0.0 0" xyz="0.990 -0.985 0.75"/>
  </joint>
  <joint name="table_bar4" type="fixed">
    <parent link="table"/>
    <child link="bar4"/>
    <origin rpy="0.0 0.0 0" xyz="-1.125 -0.985 0.75"/>
  </joint>
  <joint name="table_ceiling" type="fixed">
    <parent link="table"/>
    <child link="ceiling"/>
    <origin rpy="0.0 0.0 0" xyz="0 0 1.4"/>
  </joint>
  <joint name="table_p_joint2" type="prismatic">
    <parent link="table"/>
    <child link="table_station2"/>
    <origin rpy="0.0 0.0 0" xyz="0 0 0"/>
    <axis xyz="0 0 1"/>
    <limit effort="30" lower="-1.65" upper="0.084" velocity="1.0"/>
  </joint>
  <joint name="table_p_joint1" type="prismatic">
    <parent link="table"/>
    <child link="table_station1"/>
    <origin rpy="0.0 0.0 0" xyz="0 0 0"/>
    <axis xyz="0 0 1"/>
    <limit effort="30" lower="-0.028" upper="0.375" velocity="1.0"/>
  </joint>
  <joint name="table_joint1" type="fixed">
    <parent link="table"/>
    <child link="table_link1"/>
    <origin rpy="0.0 0.0 0" xyz="0 0 0"/>
  </joint>
  <joint name="table_joint2" type="fixed">
    <parent link="table"/>
    <child link="table_link2"/>
    <origin rpy="0.0 0.0 0" xyz="0 0 0"/>
  </joint>
  <material name="blue">
    <color rgba="0 0 0.8 1"/>
  </material>
  <material name="black">
    <color rgba="0 0 0 1"/>
  </material>
  <material name="white">
    <color rgba="1 1 1 1"/>
  </material>
  <material name="light_grey">
    <color rgba="0.4 0.4 0.4 1.0"/>
  </material>
  <link name="station_base_link">
    <visual>
      <geometry>
        <box size="0.45 1.98 0.69"/>
      </geometry>
      <origin xyz="0 0 0"/>
      <material name="light_grey"/>
    </visual>
    <collision>
      <origin xyz="0 0 0"/>
      <geometry>
        <box size="0.13 0.18 0.05"/>
      </geometry>
    </collision>
  </link>
  <link name="2ndb">
    <visual>
      <geometry>
        <box size="0.185 1.45 0.19"/>
      </geometry>
      <origin xyz="0 0 0"/>
      <material name="light_grey"/>
    </visual>
    <collision>
      <origin xyz="0 0 0"/>
      <geometry>
        <box size="0.13 0.18 0.005"/>
      </geometry>
    </collision>
  </link>
  <link name="3ndb">
    <visual>
      <geometry>
        <box size="0.185 1.45 0.09"/>
      </geometry>
      <origin xyz="0 0 0"/>
      <material name="blue"/>
    </visual>
    <collision>
      <origin xyz="0 0 0"/>
      <geometry>
        <box size="0.185 1.45 0.09"/>
      </geometry>
    </collision>
  </link>
  <link name="plate1">
    <visual>
      <geometry>
        <box size="0.18 0.35 0.01"/>
      </geometry>
      <origin xyz="0 0 0"/>
      <material name="white"/>
    </visual>
    <collision>
      <origin xyz="0 0 0"/>
      <geometry>
        <box size="0.18 0.35 0.01"/>
      </geometry>
    </collision>
    <joint name="joint2" type="fixed">
      <parent link="2ndb"/>
      <child link="3ndb"/>
      <origin xyz="0.185 0 -0.05"/>
    </joint>
  </link>
  <link name="plate2">
    <visual>
      <geometry>
        <box size="0.2 0.6 0.01"/>
      </geometry>
      <origin xyz="0 0 0"/>
      <material name="white"/>
    </visual>
    <collision>
      <origin xyz="0 0 0"/>
      <geometry>
        <box size="0.2 0.6 0.01"/>
      </geometry>
    </collision>
    <joint name="joint2" type="fixed">
      <parent link="2ndb"/>
      <child link="3ndb"/>
      <origin xyz="0.185 0 -0.05"/>
    </joint>
  </link>
  <joint name="joint1" type="fixed">
    <parent link="station_base_link"/>
    <child link="2ndb"/>
    <origin xyz="-0.0525 0.05 0.44"/>
  </joint>
  <joint name="joint2" type="fixed">
    <parent link="2ndb"/>
    <child link="3ndb"/>
    <origin xyz="0.185 0 -0.05"/>
  </joint>
  <joint name="joint3" type="fixed">
    <parent link="3ndb"/>
    <child link="plate1"/>
    <origin xyz="0 0 0.05"/>
  </joint>
  <joint name="joint4" type="fixed">
    <parent link="2ndb"/>
    <child link="plate2"/>
    <origin xyz="0 0 0.1"/>
  </joint>
  <link name="world"/>
  <joint name="world_table" type="fixed">
    <parent link="world"/>
    <child link="table"/>
    <origin rpy="0.0 0.0 0" xyz="00 0.0 0.8"/>
  </joint>
  <joint name="rob1_robot_body" type="fixed">
    <parent link="table"/>
    <child link="rob1_world"/>
    <axis xyz="0 0 0"/>
    <origin rpy="0 0 0" xyz="0.096 0.810 0.01"/>
  </joint>
  <joint name="rob2_robot_body" type="fixed">
    <parent link="table"/>
    <child link="rob2_world"/>
    <axis xyz="0 0 0"/>
    <origin rpy="0 0 3.14159" xyz="0.10 -0.690 0.01"/>
  </joint>
  <link name="camera_center_1"/>
  <joint name="basler_joint" type="fixed">
    <parent link="rob1_real_ee_link"/>
    <!-- <parent link="rob1_robotiq_arg2f_base_link" /> -->
    <child link="camera_center_1"/>
    <origin rpy="1.5707 0 0" xyz="0 0.05785 0.0721"/>
  </joint>
  <link name="camera_center_2"/>
  <joint name="basler_joint_2" type="fixed">
    <parent link="rob2_real_ee_link"/>
    <child link="camera_center_2"/>
    <origin rpy="1.5707 0 0" xyz="0 0.05785 0.0721"/>
  </joint>
  <link name="rob1_screw_tool_link"/>
  <joint name="rob1_screw_tool_joint" type="fixed">
    <parent link="rob1_real_ee_link"/>
    <child link="rob1_screw_tool_link"/>
    <origin rpy="-1.5707 -1.5707 3.1415" xyz="0 -0.1115 0.144"/>
  </joint>
  <link name="rob2_screw_tool_link"/>
  <joint name="rob2_screw_tool_joint" type="fixed">
    <parent link="rob2_real_ee_link"/>
    <child link="rob2_screw_tool_link"/>
    <origin rpy="-1.5707 -1.5707 3.1415" xyz="0 -0.1115 0.144"/>
  </joint>
  <joint name="station_joint" type="fixed">
    <parent link="table"/>
    <child link="station_base_link"/>
    <origin rpy="0 0 3.14" xyz="0.825 0 -0.455"/>
  </joint>
</robot>

